Workbook

Sheet Tổng quan
A1: ANGI – Từ điển dữ liệu (Data Dictionary)
A4: STT | B4: Schema | C4: Tên bảng | D4: Mô tả bảng | E4: Số trường
A5: 1 | B5: core | C5: roles | D5: Danh mục role: Traveler, Restaurant Owner, Mod, Admin | E5: =COUNTIF(Core!$A:$A,C5) -> 3
A6: 2 | B6: core | C6: users | D6: Tài khoản người dùng (mỗi tài khoản 1 role) | E6: =COUNTIF(Core!$A:$A,C6) -> 15
A7: 3 | B7: core | C7: permissions | D7: Danh mục quyền chi tiết | E7: =COUNTIF(Core!$A:$A,C7) -> 3
A8: 4 | B8: core | C8: role_permissions | D8: Quyền mặc định của từng role | E8: =COUNTIF(Core!$A:$A,C8) -> 2
A9: 5 | B9: core | C9: user_permissions | D9: Ghi đè quyền cho từng user (Admin quản lý quyền của Mod) | E9: =COUNTIF(Core!$A:$A,C9) -> 5
A10: 6 | B10: core | C10: user_external_logins | D10: Liên kết đăng nhập Google | E10: =COUNTIF(Core!$A:$A,C10) -> 5
A11: 7 | B11: core | C11: user_tokens | D11: Token xác minh email và reset mật khẩu | E11: =COUNTIF(Core!$A:$A,C11) -> 7
A12: 8 | B12: core | C12: user_sessions | D12: Phiên đăng nhập / refresh token | E12: =COUNTIF(Core!$A:$A,C12) -> 8
A13: 9 | B13: core | C13: media_files | D13: File upload dùng chung (ảnh, giấy tờ) | E13: =COUNTIF(Core!$A:$A,C13) -> 7
A14: 10 | B14: core | C14: restaurants | D14: Nhà hàng (mỗi Owner 1 nhà hàng) | E14: =COUNTIF(Core!$A:$A,C14) -> 24
A15: 11 | B15: core | C15: restaurant_images | D15: Ảnh của nhà hàng | E15: =COUNTIF(Core!$A:$A,C15) -> 3
A16: 12 | B16: core | C16: restaurant_business_hours | D16: Giờ mở cửa theo ngày, nhiều ca/ngày | E16: =COUNTIF(Core!$A:$A,C16) -> 5
... A42: 38 | B42: core | C42: outbox_messages | D42: Transactional outbox đồng bộ core sang recommendation | E42: =COUNTIF(Core!$A:$A,C42) -> 12
A43: 39 | B43: recommendation | C43: algorithm_configs | D43: Cấu hình thuật toán có phiên bản | E43: =COUNTIF(Recommendation!$A:$A,C43) -> 5
A44: 40 | B44: recommendation | C44: survey_option_vectors | D44: Quy lựa chọn khảo sát thành vector 12 chiều | E44: =COUNTIF(Recommendation!$A:$A,C44) -> 4
A45: 41 | B45: recommendation | C45: dish_vectors | D45: Vector 12 chiều của món do AI sinh | E45: =COUNTIF(Recommendation!$A:$A,C45) -> 15
A46: 42 | B46: recommendation | C46: user_preference_vectors | D46: Vector user và bộ đếm m, N_total | E46: =COUNTIF(Recommendation!$A:$A,C46) -> 10
A47: 43 | B47: recommendation | C47: user_dish_scores | D47: Implicit S, n, N_i theo cặp user-món | E47: =COUNTIF(Recommendation!$A:$A,C47) -> 8
A48: 44 | B48: recommendation | C48: dish_stats | D48: Like/dislike cộng đồng cho Wilson | E48: =COUNTIF(Recommendation!$A:$A,C48) -> 4
A49: 45 | B49: recommendation | C49: interaction_events | D49: Log like/dislike append-only (nguồn sự thật) | E49: =COUNTIF(Recommendation!$A:$A,C49) -> 10
A50: 46 | B50: recommendation | C50: recommendation_logs | D50: Mỗi lần gọi /recommendations | E50: =COUNTIF(Recommendation!$A:$A,C50) -> 11
A51: 47 | B51: recommendation | C51: recommendation_items | D51: Điểm từng tầng của từng món trong một lần gợi ý | E51: =COUNTIF(Recommendation!$A:$A,C51) -> 14
C53: Tổng số trường | E53: =SUM(E5:E51) -> 380
C54: Số bảng core | E54: =COUNTIF(B5:B51,"core") -> 38
C55: Số bảng recommendation | E55: =COUNTIF(B5:B51,"recommendation") -> 9
A57: Thay đổi Ver1.1 (04/10/2026)

Sheet Core
A1: Tên bảng | B1: Tên trường | C1: Kiểu dữ liệu | D1: Not null / Nullable | E1: Mô tả trường | F1: Khóa | G1: Mặc định
A2: roles — Danh mục role: Traveler, Restaurant Owner, Mod, Admin
A3: roles | B3: id | C3: smallint | D3: NOT NULL | E3: Khóa chính role | F3: PK
A4: roles | B4: code | C4: character varying(30) | D4: NOT NULL | E4: TRAVELER, RESTAURANT_OWNER, MOD, ADMIN | F4: UK
A5: roles | B5: name | C5: character varying(100) | D5: NOT NULL | E5: Tên hiển thị của role
A6: users — Tài khoản người dùng (mỗi tài khoản 1 role)
A7: users | B7: id | C7: integer | D7: NOT NULL | E7: Khóa chính người dùng; cũng là user_id bên recommendation | F7: PK
A8: users | B8: email | C8: citext | D8: NOT NULL | E8: Email đăng nhập, không phân biệt hoa thường; duy nhất trong các tài khoản chưa xóa | F8: UK (deleted_at IS NULL)
A9: users | B9: role_id | C9: smallint | D9: NOT NULL | E9: Role duy nhất của tài khoản (Traveler, Restaurant Owner, Mod, Admin) | F9: FK → roles
A10: users | B10: password_hash | C10: text | D10: NULL | E10: NULL nếu chỉ đăng nhập Google
A11: users | B11: display_name | C11: character varying(100) | D11: NOT NULL | E11: Tên hiển thị
A12: users | B12: avatar_media_id | C12: bigint | D12: NULL | E12: Ảnh đại diện (media_files, purpose = avatar); NULL = chưa có ảnh | F12: FK → media_files
A13: users | B13: phone | C13: character varying(20) | D13: NULL | E13: Số điện thoại
A14: users | B14: bio | C14: character varying(500) | D14: NULL | E14: Giới thiệu ngắn
A15: users | B15: email_verified_at | C15: timestamp with time zone | D15: NULL | E15: Thời điểm xác minh email; NULL = chưa xác minh
A16: users | B16: status | C16: character varying(20) | D16: NOT NULL | E16: Trạng thái tài khoản: pending_verification, active, suspended, banned, deactivated | G16: "pending_verification"
A17: users | B17: suspended_until | C17: timestamp with time zone | D17: NULL | E17: Chỉ dùng khi status = 'suspended'
A18: users | B18: last_login_at | C18: timestamp with time zone | D18: NULL | E18: Lần đăng nhập gần nhất
A19: users | B19: created_at | C19: timestamp with time zone | D19: NOT NULL | E19: Thời điểm tạo | G19: now()
A20: users | B20: updated_at | C20: timestamp with time zone | D20: NOT NULL | E20: Thời điểm cập nhật gần nhất | G20: now()
A21: users | B21: deleted_at | C21: timestamp with time zone | D21: NULL | E21: Thời điểm xóa mềm; NULL = chưa xóa
A22: permissions — Danh mục quyền chi tiết
A23: permissions | B23: id | C23: smallint | D23: NOT NULL | E23: Khóa chính quyền | F23: PK
A24: permissions | B24: code | C24: character varying(60) | D24: NOT NULL | E24: Vd: USER_BAN, RESTAURANT_VERIFY, MENU_APPROVE, BLOG_MODERATE | F24: UK
A25: permissions | B25: description | C25: character varying(255) | D25: NULL | E25: Mô tả quyền
A26: role_permissions — Quyền mặc định của từng role
A27: role_permissions | B27: role_id | C27: smallint | D27: NOT NULL | E27: Role được cấp quyền | F27: PK (ghép), FK → roles
A28: role_permissions | B28: permission_id | C28: smallint | D28: NOT NULL | E28: Quyền mặc định của role | F28: PK (ghép), FK → permissions
A29: user_permissions — Ghi đè quyền cho từng user (Admin quản lý quyền của Mod)
A30: user_permissions | B30: user_id | C30: integer | D30: NOT NULL | E30: User (thường là Mod) được ghi đè quyền | F30: PK (ghép), FK → users
A31: user_permissions | B31: permission_id | C31: smallint | D31: NOT NULL | E31: Quyền bị ghi đè | F31: PK (ghép), FK → permissions
A32: user_permissions | B32: effect | C32: character varying(5) | D32: NOT NULL | E32: allow = cấp thêm, deny = thu hồi so với quyền của role | G32: "allow"
A33: user_permissions | B33: granted_by | C33: integer | D33: NULL | E33: Admin thực hiện | F33: FK → users
A34: user_permissions | B34: granted_at | C34: timestamp with time zone | D34: NOT NULL | E34: Thời điểm cấp/thu | G34: now()
A35: user_external_logins — Liên kết đăng nhập Google
A36: user_external_logins | B36: id | C36: bigint | D36: NOT NULL | E36: Khóa chính | F36: PK
A37: user_external_logins | B37: user_id | C37: integer | D37: NOT NULL | E37: Tài khoản ANGI được liên kết | F37: UK (ghép), FK → users
A38: user_external_logins | B38: provider | C38: character varying(20) | D38: NOT NULL | E38: Nhà cung cấp đăng nhập (hiện chỉ google) | F38: UK (ghép)
A39: user_external_logins | B39: provider_user_id | C39: character varying(255) | D39: NOT NULL | E39: Id người dùng phía Google (claim "sub") | F39: UK (ghép)
A40: user_external_logins | B40: linked_at | C40: timestamp with time zone | D40: NOT NULL | E40: Thời điểm liên kết | G40: now()
...

Sheet Recommendation
A1: Tên bảng | B1: Tên trường | C1: Kiểu dữ liệu | D1: Not null / Nullable | E1: Mô tả trường | F1: Khóa | G1: Mặc định
A2: algorithm_configs — Cấu hình thuật toán có phiên bản
A3: algorithm_configs | B3: config_version | C3: integer | D3: NOT NULL | E3: Số phiên bản cấu hình | F3: PK
A4: algorithm_configs | B4: params | C4: jsonb | D4: NOT NULL | E4: {"beta_u":0.03,"beta_s":0.03,"k":5,"k_prime":5,"z":1.96,"gamma":0.1,"explicit_norm":"minmax_cosine","ontology_version":1}
A5: algorithm_configs | B5: is_active | C5: boolean | D5: NOT NULL | E5: Cấu hình đang dùng (chỉ 1 dòng true) | G5: false
A6: algorithm_configs | B6: note | C6: text | D6: NULL | E6: Ghi chú
A7: algorithm_configs | B7: created_at | C7: timestamp with time zone | D7: NOT NULL | E7: Thời điểm tạo | G7: now()
A8: survey_option_vectors — Quy lựa chọn khảo sát thành vector 12 chiều
A9: survey_option_vectors | B9: option_code | C9: character varying(50) | D9: NOT NULL | E9: Mã lựa chọn khảo sát do app gửi lên (bộ câu hỏi cố định ở FE) | F9: PK
A10: survey_option_vectors | B10: vec | C10: vector(12) | D10: NOT NULL | E10: Các chiều không liên quan để 0
A11: survey_option_vectors | B11: dim_mask | C11: vector(12) | D11: NOT NULL | E11: 1 ở chiều mà option này có ý kiến, 0 ở chiều còn lại
A12: survey_option_vectors | B12: updated_at | C12: timestamp with time zone | D12: NOT NULL | E12: Thời điểm cập nhật gần nhất | G12: now()
A13: dish_vectors — Vector 12 chiều của món do AI sinh
A14: dish_vectors | B14: dish_id | C14: integer | D14: NOT NULL | E14: Món (= core.dishes.id, tham chiếu mềm) | F14: PK
A15: dish_vectors | B15: vec | C15: vector(12) | D15: NULL | E15: NULL khi chưa sinh được / failed
A16: dish_vectors | B16: raw_ai_output | C16: jsonb | D16: NULL | E16: JSON gốc AI trả về
A17: dish_vectors | B17: source_hash | C17: character(64) | D17: NOT NULL | E17: Sha256(name + description ...)
A18: dish_vectors | B18: model_name | C18: character varying(100) | D18: NULL | E18: Model AI sinh vector
A19: dish_vectors | B19: ontology_version | C19: smallint | D19: NOT NULL | E19: Phiên bản ontology (12 chiều = 1) | G19: 1
A20: dish_vectors | B20: status | C20: character varying(10) | D20: NOT NULL | E20: pending, ready, failed | G20: "pending"
A21: dish_vectors | B21: attempt_count | C21: smallint | D21: NOT NULL | E21: Số lần sinh vector đã thử | G21: 0
A22: dish_vectors | B22: last_error | C22: text | D22: NULL | E22: Lỗi lần sinh gần nhất
A23: dish_vectors | B23: is_active | C23: boolean | D23: NOT NULL | E23: False khi backend xóa/ẩn món | G23: true
A24: dish_vectors | B24: name | C24: character varying(200) | D24: NULL | E24: Tên món đã nhận, dùng để sinh lại vector khi failed
A25: dish_vectors | B25: description | C25: text | D25: NULL | E25: Mô tả món đã nhận
A26: dish_vectors | B26: last_event_at | C26: timestamp with time zone | D26: NULL | E26: Occurred_at của sự kiện mới nhất đã áp dụng; sự kiện cũ hơn (đến trễ) bị bỏ qua
A27: dish_vectors | B27: created_at | C27: timestamp with time zone | D27: NOT NULL | E27: Thời điểm tạo | G27: now()
A28: dish_vectors | B28: updated_at | C28: timestamp with time zone | D28: NOT NULL | E28: Thời điểm cập nhật gần nhất | G28: now()
A29: user_preference_vectors — Vector user và bộ đếm m, N_total
A30: user_preference_vectors | B30: user_id | C30: integer | D30: NOT NULL | E30: User (= core.users.id, tham chiếu mềm) | F30: PK
A31: user_preference_vectors | B31: initial_vec | C31: vector(12) | D31: NULL | E31: Từ khảo sát; NULL nếu chưa khảo sát
A32: user_preference_vectors | B32: vec | C32: vector(12) | D32: NULL | E32: Cập nhật online; NULL = chưa có (Explicit = 0). Không lưu vector 0.
A33: user_preference_vectors | B33: survey_answer_count | C33: integer | D33: NOT NULL | E33: q = số câu trả lời khảo sát | G33: 0
A34: user_preference_vectors | B34: feedback_count | C34: integer | D34: NOT NULL | E34: Số lần like/dislike | G34: 0
A35: user_preference_vectors | B35: total_interactions | C35: integer | D35: NULL | E35: m = q + số like/dislike (cột tính tự động) | G35: (cột tính toán)
A36: user_preference_vectors | B36: total_shown | C36: bigint | D36: NOT NULL | E36: N_total = tổng số lần các món được hiển thị cho user | G36: 0
A37: user_preference_vectors | B37: survey_payload | C37: jsonb | D37: NULL | E37: Câu trả lời thô nhận được
A38: user_preference_vectors | B38: survey_at | C38: timestamp with time zone | D38: NULL | E38: Khác NULL => đã khảo sát; khảo sát chỉ nhận 1 lần (409 nếu gửi lại)
A39: user_preference_vectors | B39: updated_at | C39: timestamp with time zone | D39: NOT NULL | E39: Thời điểm cập nhật gần nhất | G39: now()
A40: user_dish_scores — Implicit S, n, N_i theo cặp user-món
...
