Workbook

Sheet Sprints
A1: Sprint | B1: Tuần | C1: Bắt đầu | D1: Kết thúc | E1: Sprint Goal | F1: Số task | G1: Story points
A2: ANGI Sprint 0 | B2: W5 | C2: 05/10/2026 | D2: 11/10/2026 | E2: Hoàn tất thiết kế (SDS v1.0, Test Plan, SRS v1.0), dựng khung dự án, DB, CI, seed data | F2: =COUNTIF(Backlog!$F:$F,A2) -> 15 | G2: =SUMIF(Backlog!$F:$F,A2,Backlog!$H:$H) -> 45
A3: ANGI Sprint 1 | B3: W6-W7 | C3: 12/10/2026 | D3: 25/10/2026 | E3: Iteration 1: Authentication & Account, Restaurant Management, Discovery, Reco phase 1 -> Software Package V1 | F3: =COUNTIF(Backlog!$F:$F,A3) -> 70 | G3: =SUMIF(Backlog!$F:$F,A3,Backlog!$H:$H) -> 153
A4: ANGI Sprint 2 | B4: W8-W9 | C4: 26/10/2026 | D4: 08/11/2026 | E4: Iteration 2: Roadmap, Feedback & Report, Blog, Notification, Reco phase 2 -> Software Package V2 | F4: =COUNTIF(Backlog!$F:$F,A4) -> 68 | G4: =SUMIF(Backlog!$F:$F,A4,Backlog!$H:$H) -> 150
A5: ANGI Sprint 3 | B5: W10-W11 | C5: 09/11/2026 | D5: 22/11/2026 | E5: Iteration 3: Moderation, Administration, Reco last phase, System Test Cases -> Software Package V3 | F5: =COUNTIF(Backlog!$F:$F,A5) -> 45 | G5: =SUMIF(Backlog!$F:$F,A5,Backlog!$H:$H) -> 108
A6: ANGI Sprint 4 | B6: W12-W13 | C6: 23/11/2026 | D6: 06/12/2026 | E6: Verification & Validation: System/Acceptance test, fix bug, User Guides, Final Software Package | F6: =COUNTIF(Backlog!$F:$F,A6) -> 10 | G6: =SUMIF(Backlog!$F:$F,A6,Backlog!$H:$H) -> 25
A7: ANGI Sprint 5 | B7: W14 | C7: 07/12/2026 | D7: 13/12/2026 | E7: Closing: Final Project Report, Presentation | F7: =COUNTIF(Backlog!$F:$F,A7) -> 2 | G7: =SUMIF(Backlog!$F:$F,A7,Backlog!$H:$H) -> 7

Sheet Team
A1: Thành viên | B1: Vai trò | C1: Người review PR
A2: Dũng | B2: PM; Recommendation System (FastAPI); DevOps, hạ tầng, database; Backend F-26 (AI generation roadmap item) | C2: Hưng
A3: Hưng | B3: Backend .NET: Authentication, Restaurant, Roadmap, Moderation (nhà hàng, menu), Administration (quyền) | C3: Dũng
A4: Trọng | B4: Backend .NET: Account, Discovery, Notification, Blog, Feedback & Report, Moderation (người dùng, nội dung) | C4: Dũng
A5: Tuấn | B5: Frontend Next.js: Owner portal, Roadmap, Admin | C5: Dũng
A6: Đức | B6: Frontend Next.js: Auth, Discovery, Blog, Moderation; Test docs, User Guide | C6: Tuấn

Sheet Epics
A1: Epic key | B1: Epic | C1: Phạm vi | D1: Start Date | E1: End Date | F1: Số task | G1: Story points
A2: EP-SETUP | B2: Project Setup & Infrastructure | C2: Repo, CI/CD, solution skeleton, DB migration, seed data, shared services | D2: 05/10/2026 | E2: 08/11/2026 | F2: =COUNTIF(Backlog!$G:$G,A2) -> 15 | G2: =SUMIF(Backlog!$G:$G,A2,Backlog!$H:$H) -> 46
A3: EP-AUTH | B3: Authentication & Account | C3: F-01..F-08 | D3: 12/10/2026 | E3: 20/10/2026 | F3: =COUNTIF(Backlog!$G:$G,A3) -> 16 | G3: =SUMIF(Backlog!$G:$G,A3,Backlog!$H:$H) -> 30
A4: EP-NOTI | B4: Notification | C4: F-09..F-10 | D4: 26/10/2026 | E4: 27/10/2026 | F4: =COUNTIF(Backlog!$G:$G,A4) -> 4 | G4: =SUMIF(Backlog!$G:$G,A4,Backlog!$H:$H) -> 6
A5: EP-DISC | B5: Dish & Restaurant Discovery | C5: F-11..F-18 | D5: 12/10/2026 | E5: 20/10/2026 | F5: =COUNTIF(Backlog!$G:$G,A5) -> 16 | G5: =SUMIF(Backlog!$G:$G,A5,Backlog!$H:$H) -> 38
A6: EP-ROAD | B6: Roadmap | C6: F-19..F-30 | D6: 26/10/2026 | E6: 03/11/2026 | F6: =COUNTIF(Backlog!$G:$G,A6) -> 24 | G6: =SUMIF(Backlog!$G:$G,A6,Backlog!$H:$H) -> 65
A7: EP-FBR | B7: Restaurant Feedback & Report | C7: F-31..F-33 | D7: 31/10/2026 | E7: 03/11/2026 | F7: =COUNTIF(Backlog!$G:$G,A7) -> 6 | G7: =SUMIF(Backlog!$G:$G,A7,Backlog!$H:$H) -> 12
A8: EP-BLOG | B8: Blog | C8: F-34..F-42 | D8: 26/10/2026 | E8: 02/11/2026 | F8: =COUNTIF(Backlog!$G:$G,A8) -> 18 | G8: =SUMIF(Backlog!$G:$G,A8,Backlog!$H:$H) -> 36
A9: EP-REST | B9: Restaurant Management | C9: F-43..F-51 | D9: 12/10/2026 | E9: 20/10/2026 | F9: =COUNTIF(Backlog!$G:$G,A9) -> 18 | G9: =SUMIF(Backlog!$G:$G,A9,Backlog!$H:$H) -> 45
A10: EP-MOD | B10: Moderation | C10: F-52..F-62 | D10: 09/11/2026 | E10: 17/11/2026 | F10: =COUNTIF(Backlog!$G:$G,A10) -> 22 | G10: =SUMIF(Backlog!$G:$G,A10,Backlog!$H:$H) -> 51
A11: EP-ADMIN | B11: Administration | C11: F-63..F-66 | D11: 09/11/2026 | E11: 16/11/2026 | F11: =COUNTIF(Backlog!$G:$G,A11) -> 8 | G11: =SUMIF(Backlog!$G:$G,A11,Backlog!$H:$H) -> 28
A12: EP-RECO | B12: Recommendation System | C12: Recommendation service (FastAPI) phase 1-3 | D12: 12/10/2026 | E12: 16/11/2026 | F12: =COUNTIF(Backlog!$G:$G,A12) -> 11 | G12: =SUMIF(Backlog!$G:$G,A12,Backlog!$H:$H) -> 37
A13: EP-DOC | B13: Documentation & Reports | C13: SRS, SDS, Test docs, User Guides, Final Report | D13: 05/10/2026 | E13: 13/12/2026 | F13: =COUNTIF(Backlog!$G:$G,A13) -> 14 | G13: =SUMIF(Backlog!$G:$G,A13,Backlog!$H:$H) -> 31
A14: EP-QA | B14: Testing & Release | C14: Integration/System/Acceptance test, bug fixing, software packages | D14: 19/10/2026 | E14: 06/12/2026 | F14: =COUNTIF(Backlog!$G:$G,A14) -> 38 | G14: =SUMIF(Backlog!$G:$G,A14,Backlog!$H:$H) -> 63

Sheet Backlog
A1: Issue ID | B1: Type | C1: Summary | D1: Description | E1: Assignee | F1: Sprint | G1: Epic | H1: Story Points | I1: Start Date | J1: Due Date | K1: Labels | L1: Jira key | M1: Critical path | N1: Float (ngày) | O1: Priority
A2: T133 | B2: Task | C2: Tạo GitHub repo (backend, frontend, reco), branch strategy, PR template, rule review | D2: Cấu hình đúng commit_guide.md: nhánh main/dev, nhánh làm việc <type>/ANGI-xxx-mô-tả tạo từ dev; PR vào dev, squash merge, cần 1 approve. Bảo vệ main và dev (không push thẳng). | E2: Dũng | F2: ANGI Sprint 0 | G2: EP-SETUP | H2: 2 | I2: 05/10/2026 | J2: 05/10/2026 | K2: devops | L2: ANGI-14 | N2: 8.3 | O2: Medium
A3: T157 | B3: Task | C3: Report 4: SDS v1.0 (High Level Design) | D3: Cả team cùng viết, mỗi người viết phần module/feature mình làm. Dũng tổng hợp và duyệt cuối. | E3: Dũng | F3: ANGI Sprint 0 | G3: EP-DOC | H3: 3 | I3: 05/10/2026 | J3: 05/10/2026 | K3: docs | L3: ANGI-15 | N3: 69 | O3: Medium
A4: T134 | B4: Task | C4: Docker Compose môi trường dev: PostgreSQL 16 + pgvector | D4: Mỗi dev chạy được DB local bằng 1 lệnh; tạo 2 DB role riêng cho backend (schema core) và reco (schema recommendation) như project_architecture.md mục 6. Viết hướng dẫn chạy vào README. | E4: Dũng | F4: ANGI Sprint 0 | G4: EP-SETUP | H4: 2 | I4: 05/10/2026 | J4: 06/10/2026 | K4: devops | L4: ANGI-16 | N4: 8.5 | O4: Medium
A5: T140 | B5: Task | C5: Shared service: upload ảnh/tài liệu (Cloudinary) | D5: Interface ở Application/Common/Interfaces/Services, implementation ở Infrastructure/Services (project_architecture.md mục 2). Dùng cho MEDIA-01 và bảng media_files. | E5: Hưng | F5: ANGI Sprint 0 | G5: EP-SETUP | H5: 2 | I5: 05/10/2026 | J5: 07/10/2026 | K5: backend | L5: ANGI-17 | N5: 11.5 | O5: Medium
A6: T141 | B6: Task | C6: Shared service: gửi email (Brevo) + template xác minh / reset mật khẩu | D6: Interface ở Application/Common/Interfaces/Services, implementation ở Infrastructure/Services (project_architecture.md mục 2). Dùng cho F-01, F-02, F-05. | E6: Trọng | F6: ANGI Sprint 0 | G6: EP-SETUP | H6: 2 | I6: 05/10/2026 | J6: 08/10/2026 | K6: backend | L6: ANGI-18 | N6: 10.8 | O6: Medium
A7: T142 | B7: Task | C7: Khung Next.js: layout, routing theo role, API client, auth guard, UI kit | D7: API client đọc base URL từ env, lấy dữ liệu từ field data của ApiResponse, rẽ nhánh lỗi theo errorCode (sheet Mã lỗi của ANGI_API_Design_Ver1.7), xử lý refresh token (AUTH-06). | E7: Tuấn | F7: ANGI Sprint 0 | G7: EP-SETUP | H7: 5 | I7: 05/10/2026 | J7: 11/10/2026 | K7: frontend | L7: ANGI-19 | N7: 8.1 | O7: High
A8: T143 | B8: Task | C8: Wireframe/mockup các màn hình Iteration 1 | D8: Theo các use case Iteration 1 trong ANGI_Use_Case_Basic_Descriptions_Ver1.0. | E8: Đức | F8: ANGI Sprint 0 | G8: EP-SETUP | H8: 3 | I8: 05/10/2026 | J8: 11/10/2026 | K8: frontend | L8: ANGI-20 | N8: 8.1 | O8: Medium
A9: T135 | B9: Task | C9: Database: ANGIContext schema core, base class, initial migration | D9: Map toàn bộ bảng schema core theo ANGI_Data_Dictionary_Ver1.1 vào ANGIContext (IEntityTypeConfiguration mỗi bảng), BaseEntity + ISoftDelete, enum lưu đúng giá trị chữ thường như sheet Enum của ANGI_API_Design_Ver1.7. Initial migration gồm cả CHECK, citext và trigger outbox (migrationBuilder.Sql). Từ đây schema core chỉ đổi qua EF migration (commit_guide.md mục 10). | Làm sau: Docker Compose môi trường dev: PostgreSQL 16 + pgvector. | E9: Dũng | F9: ANGI Sprint 0 | G9: EP-SETUP | H9: 5 | I9: 06/10/2026 | J9: 08/10/2026 | K9: devops | L9: ANGI-21 | N9: 8.5 | O9: High
A10: T158 | B10: Task | C10: Report 5: Test Planning | D10: Report 5: Test Planning | E10: Đức | F10: ANGI Sprint 0 | G10: EP-DOC | H10: 2 | I10: 07/10/2026 | J10: 08/10/2026 | K10: docs | L10: ANGI-22 | N10: 66 | O10: Medium
A11: T139 | B11: Task | C11: Backend: ExceptionHandlingMiddleware, cấu hình JWT, CORS, rate limit | D11: Mọi response bọc trong ApiResponse<T> (success, message, errorCode, data, errors) theo coding_rule.md mục 5. Middleware map exception sang status + errorCode theo coding_rule.md mục 7 và sheet Mã lỗi của ANGI_API_Design_Ver1.7; 401, 403, 429 và lỗi model binding cũng trả ApiResponse. JWT, CORS, rate limit theo project_architecture.md mục 4–5. | E11: Hưng | F11: ANGI Sprint 0 | G11: EP-SETUP | H11: 3 | I11: 07/10/2026 | J11: 11/10/2026 | K11: backend | L11: ANGI-23 | N11: 6.4 | O11: Medium
A12: T136 | B12: Task | C12: CI GitHub Actions: build + unit test cho .NET, FastAPI, Next.js | D12: Chạy cho mọi PR vào dev; PR đỏ thì không được merge. | Làm sau: Database: ANGIContext schema core, base class, initial migration. | E12: Dũng | F12: ANGI Sprint 0 | G12: EP-SETUP | H12: 3 | I12: 08/10/2026 | J12: 09/10/2026 | K12: devops | L12: ANGI-24 | N12: 65.8 | O12: Medium
A13: T144 | B13: Task | C13: Ghi audit log cho thao tác quan trọng | D13: Ghi vào bảng audit_logs (ANGI_Data_Dictionary_Ver1.1): đăng nhập, khóa/mở khóa user, duyệt nhà hàng/menu, ẩn nội dung, đổi quyền. Dữ liệu cho F-55 và F-64 ở Iteration 3. | Làm sau: Database: ANGIContext schema core, base class, initial migration. | E13: Trọng | F13: ANGI Sprint 0 | G13: EP-SETUP | H13: 2 | I13: 08/10/2026 | J13: 11/10/2026 | K13: backend | L13: ANGI-25 | N13: 63 | O13: Medium
... A37: T091 | B37: Task | C37: [BE] F-46 Update Status | D37: Use case F-46 Update Status (Actor: Restaurant Owner). Allows a Restaurant Owner to update the restaurant's operating status, such as open or temporarily closed. The system saves the new status and uses it when displaying or providing restaurant information. Endpoint cần làm: - OWN-05 PUT /api/v1/owner/restaurant/operating-status Tài liệu: ANGI_Use_Case_Basic_Descriptions_Ver1.0 (use case), ANGI_API_Design_Ver1.7 (sheet Backend API, Chi tiết Request-Response, Mã lỗi), ANGI_Data_Dictionary_Ver1.1 (bảng), coding_rule.md. DoD: Endpoint trả đúng request/response và mã lỗi như ANGI_API_Design_Ver1.7; code theo coding_rule.md; unit test tối thiểu 2 method; hiện trên Scalar; PR được Dũng review. | E37: Trọng | F37: ANGI Sprint 1 | G37: EP-REST | H37: 1 | I37: 14/10/2026 | J37: 14/10/2026 | K37: backend iteration1 | L37: ANGI-49 | N37: 5 | O37: Medium
A38: T148 | B38: Task | C38: Reco P1: Sinh dish vector (RECO-01 upsert, RECO-02 deactivate) | D38: [CRITICAL PATH] Task này nằm trên đường găng: dự phòng tối đa 1 ngày. Phải xong đúng Due Date 15/10/2026; trễ 1 ngày thì mốc "Software Package Version 1" (25/10/2026) bị trễ theo. Ảnh hưởng trực tiếp tới: Reco P1: Cold start (Pooled Wilson) + Content-based, RECO-05 /recommendations, RECO-06 /impressions; Code freeze + tích hợp Iteration 1: merge PR vào dev, chạy toàn hệ thống. Cần xong trước khi bắt đầu: Reco P1: Chuẩn hóa dữ liệu + ontology 12 chiều. Gặp vướng thì báo ngay trong ngày cho Dũng (PM), không đợi họp. Recommendation_System_Design_Ver1.0 mục 2.4. Deliverable: Dish Vector. | Làm sau: Reco P1: Chuẩn hóa dữ liệu + ontology 12 chiều. | E38: Dũng | F38: ANGI Sprint 1 | G38: EP-RECO | H38: 3 | I38: 14/10/2026 | J38: 15/10/2026 | K38: reco critical-path | L38: ANGI-50 | M38: Có | N38: 1.4 | O38: Highest
A39: T014 | B39: Task | C39: [FE] F-07 Manage Personal Profile | D39: Use case F-07 Manage Personal Profile (Actor: Registered User). Allows a Registered User to view and update the editable personal information of their account, such as display name and related profile details. The system validates the input and saves valid changes. Endpoint cần gọi: - ME-01 GET /api/v1/me - ME-02 PATCH /api/v1/me - MEDIA-01 POST /api/v1/media Tài liệu: ANGI_Use_Case_Basic_Descriptions_Ver1.0 (use case), ANGI_API_Design_Ver1.7 (sheet JSON mẫu để làm mock data, sheet Mã lỗi để hiện thông báo lỗi). DoD: Màn hình chạy với mock data đúng sheet JSON mẫu, chuyển sang API thật khi BE merge; responsive; PR được Tuấn review. | E39: Đức | F39: ANGI Sprint 1 | G39: EP-AUTH | H39: 2 | I39: 14/10/2026 | J39: 15/10/2026 | K39: frontend iteration1 | L39: ANGI-51 | N39: 6.5 | O39: Medium
A40: T095 | B40: Task | C40: [BE] F-48 View Verification Status | D40: Use case F-48 View Verification Status (Actor: Restaurant Owner). Allows a Restaurant Owner to view the current status of the restaurant verification request, such as pending, approved, or rejected, along with any feedback. Endpoint cần làm: - OWN-07 GET /api/v1/owner/restaurant/verifications Tài liệu: ANGI_Use_Case_Basic_Descriptions_Ver1.0 (use case), ANGI_API_Design_Ver1.7 (sheet Backend API, Chi tiết Request-Response, Mã lỗi), ANGI_Data_Dictionary_Ver1.1 (bảng), coding_rule.md. DoD: Endpoint trả đúng request/response và mã lỗi như ANGI_API_Design_Ver1.7; code theo coding_rule.md; unit test tối thiểu 2 method; hiện trên Scalar; PR được Dũng review. | E40: Trọng | F40: ANGI Sprint 1 | G40: EP-REST | H40: 1 | I40: 14/10/2026 | J40: 15/10/2026 | K40: backend iteration1 | L40: ANGI-52 | N40: 4.8 | O40: Medium
A41: T099 | B41: Task | C41: [BE] F-50 Manage Restaurant Menu | D41: Use case F-50 Manage Restaurant Menu (Actor: Restaurant Owner). Allows a Restaurant Owner to manage the restaurant's menu, including adding, editing, or removing dishes and related information. Changes may need to go through an approval process depending on the status of the restaurant and the menu. Endpoint cần làm: - OWN-09 GET /api/v1/owner/restaurant/menu - OWN-10 PUT /api/v1/owner/restaurant/menu/dishes/{dishId}/availability - OWN-11 POST /api/v1/owner/restaurant/menu-submissions - OWN-12 GET /api/v1/owner/restaurant/menu-submissions - OWN-13 GET /api/v1/owner/restaurant/menu-submissions/{submissionId} - OWN-14 POST /api/v1/owner/restaurant/menu-submissions/{submissionId}/items - OWN-15 PATCH /api/v1/owner/restaurant/menu-submissions/{submissionId}/items/{itemId} - OWN-16 DELETE /api/v1/owner/restaurant/menu-submissions/{submissionId}/items/{itemId} - OWN-18 POST /api/v1/owner/restaurant/menu-submissions/{submissionId}/cancel Ghi chú: Sửa menu = soạn bản menu mới (menu_submissions, menu_submission_items); menu đang hiển thị giữ nguyên đến khi Mod duyệt. Tài liệu: ANGI_Use_Case_Basic_Descriptions_Ver1.0 (use case), ANGI_API_Design_Ver1.7 (sheet Backend API, Chi tiết Request-Response, Mã lỗi), ANGI_Data_Dictionary_Ver1.1 (bảng), coding_rule.md. DoD: Endpoint trả đúng request/response và mã lỗi như ANGI_API_Design_Ver1.7; code theo coding_rule.md; unit test tối thiểu 2 method; hiện trên Scalar; PR được Dũng review. | E41: Hưng | F41: ANGI Sprint 1 | G41: EP-REST | H41: 5 | I41: 14/10/2026 | J41: 15/10/2026 | K41: backend iteration1 | L41: ANGI-53 | N41: 4.3 | O41: High
A42: T016 | B42: Task | C42: [FE] F-08 Change Password | D42: Use case F-08 Change Password (Actor: Registered User). Allows a logged-in Registered User to change their current password. The system requires the current password, validates the new password, and updates it if all conditions are met. Endpoint cần gọi: - ME-03 PUT /api/v1/me/password Tài liệu: ANGI_Use_Case_Basic_Descriptions_Ver1.0 (use case), ANGI_API_Design_Ver1.7 (sheet JSON mẫu để làm mock data, sheet Mã lỗi để hiện thông báo lỗi). DoD: Màn hình chạy với mock data đúng sheet JSON mẫu, chuyển sang API thật khi BE merge; responsive; PR được Tuấn review. | E42: Đức | F42: ANGI Sprint 1 | G42: EP-AUTH | H42: 1 | I42: 15/10/2026 | J42: 15/10/2026 | K42: frontend iteration1 | L42: ANGI-54 | N42: 6.1 | O42: Medium
A43: T092 | B43: Task | C43: [FE] F-46 Update Status | D43: Use case F-46 Update Status (Actor: Restaurant Owner). Allows a Restaurant Owner to update the restaurant's operating status, such as open or temporarily closed. The system saves the new status and uses it when displaying or providing restaurant information. Endpoint cần gọi: - OWN-05 PUT /api/v1/owner/restaurant/operating-status Tài liệu: ANGI_Use_Case_Basic_Descriptions_Ver1.0 (use case), ANGI_API_Design_Ver1.7 (sheet JSON mẫu để làm mock data, sheet Mã lỗi để hiện thông báo lỗi). DoD: Màn hình chạy với mock data đúng sheet JSON mẫu, chuyển sang API thật khi BE merge; responsive; PR được Dũng review. | E43: Tuấn | F43: ANGI Sprint 1 | G43: EP-REST | H43: 1 | I43: 15/10/2026 | J43: 15/10/2026 | K43: frontend iteration1 | L43: ANGI-55 | N43: 6.6 | O43: Medium
A44: T097 | B44: Task | C44: [BE] F-49 Resubmit Verification | D44: Use case F-49 Resubmit Verification (Actor: Restaurant Owner). Allows a Restaurant Owner to resubmit a verification request after the previous submission was rejected or more information was requested. The system receives the updated data and creates a new submission for review. Endpoint cần làm: - OWN-08 POST /api/v1/owner/restaurant/verifications/{verificationId}/resubmit Tài liệu: ANGI_Use_Case_Basic_Descriptions_Ver1.0 (use case), ANGI_API_Design_Ver1.7 (sheet Backend API, Chi tiết Request-Response, Mã lỗi), ANGI_Data_Dictionary_Ver1.1 (bảng), coding_rule.md. DoD: Endpoint trả đúng request/response và mã lỗi như ANGI_API_Design_Ver1.7; code theo coding_rule.md; unit test tối thiểu 2 method; hiện trên Scalar; PR được Dũng review. | E44: Trọng | F44: ANGI Sprint 1 | G44: EP-REST | H44: 2 | I44: 15/10/2026 | J44: 15/10/2026 | K44: backend iteration1 | L44: ANGI-56 | N44: 4.2 | O44: Medium
A45: T150 | B45: Task | C45: Reco P1: Cold start (Pooled Wilson) + Content-based, RECO-05 /recommendations, RECO-06 /impressions | D45: [CRITICAL PATH] Task này nằm trên đường găng: dự phòng tối đa 1 ngày. Phải xong đúng Due Date 16/10/2026; trễ 1 ngày thì mốc "Software Package Version 1" (25/10/2026) bị trễ theo. Ảnh hưởng trực tiếp tới: [BE] F-12 Browse Dish; [BE] F-11 View Home Page; Code freeze + tích hợp Iteration 1: merge PR vào dev, chạy toàn hệ thống. Cần xong trước khi bắt đầu: Reco P1: Sinh dish vector (RECO-01 upsert, RECO-02 deactivate); Reco P1: User vector từ khảo sát (RECO-03, RECO-09). Gặp vướng thì báo ngay trong ngày cho Dũng (PM), không đợi họp. Recommendation_System_Design_Ver1.0 mục 3.3 và 3.6. Deliverable: Recommend for new user. | Làm sau: Reco P1: Sinh dish vector (RECO-01 upsert, RECO-02 deactivate), Reco P1: User vector từ khảo sát (RECO-03, RECO-09). | E45: Dũng | F45: ANGI Sprint 1 | G45: EP-RECO | H45: 5 | I45: 15/10/2026 | J45: 16/10/2026 | K45: reco critical-path | L45: ANGI-57 | M45: Có | N45: 1.4 | O45: Highest
A46: T003 | B46: Task | C46: [BE] F-02 Verify Email | D46: Use case F-02 Verify Email (Actor: Guest). Allows a user to verify the email address of their account through a verification link or code sent by the system. The system checks the validity and expiry of the verification data, then updates the account's email status when verification succeeds. Endpoint cần làm: - AUTH-02 POST /api/v1/auth/verify-email - AUTH-03 POST /api/v1/auth/verify-email/resend Ghi chú: Token lưu dạng hash trong user_tokens, dùng 1 lần; resend giới hạn 1 lần / 60 giây. Tài liệu: ANGI_Use_Case_Basic_Descriptions_Ver1.0 (use case), ANGI_API_Design_Ver1.7 (sheet Backend API, Chi tiết Request-Response, Mã lỗi), ANGI_Data_Dictionary_Ver1.1 (bảng), coding_rule.md. DoD: Endpoint trả đúng request/response và mã lỗi như ANGI_API_Design_Ver1.7; code theo coding_rule.md; unit test tối thiểu 2 method; hiện trên Scalar; PR được Dũng review. | E46: Hưng | F46: ANGI Sprint 1 | G46: EP-AUTH | H46: 2 | I46: 15/10/2026 | J46: 16/10/2026 | K46: backend iteration1 | L46: ANGI-58 | N46: 3.8 | O46: Medium
A47: T004 | B47: Task | C47: [FE] F-02 Verify Email | D47: Use case F-02 Verify Email (Actor: Guest). Allows a user to verify the email address of their account through a verification link or code sent by the system. The system checks the validity and expiry of the verification data, then updates the account's email status when verification succeeds. Endpoint cần gọi: - AUTH-02 POST /api/v1/auth/verify-email - AUTH-03 POST /api/v1/auth/verify-email/resend Tài liệu: ANGI_Use_Case_Basic_Descriptions_Ver1.0 (use case), ANGI_API_Design_Ver1.7 (sheet JSON mẫu để làm mock data, sheet Mã lỗi để hiện thông báo lỗi). DoD: Màn hình chạy với mock data đúng sheet JSON mẫu, chuyển sang API thật khi BE merge; responsive; PR được Tuấn review. | E47: Đức | F47: ANGI Sprint 1 | G47: EP-AUTH | H47: 1 | I47: 15/10/2026 | J47: 16/10/2026 | K47: frontend iteration1 | L47: ANGI-59 | N47: 5.8 | O47: Medium
A48: T025 | B48: Task | C48: [BE] F-13 View Dish Detail | D48: Use case F-13 View Dish Detail (Actor: Guest, Traveler). Allows a Guest or Traveler to view the details of a dish, including its name, description, characteristics, related information, and the restaurant that serves it. Endpoint cần làm: - DISH-02 GET /api/v1/dishes/{dishId} Tài liệu: ANGI_Use_Case_Basic_Descriptions_Ver1.0 (use case), ANGI_API_Design_Ver1.7 (sheet Backend API, Chi tiết Request-Response, Mã lỗi), ANGI_Data_Dictionary_Ver1.1 (bảng), coding_rule.md. DoD: Endpoint trả đúng request/response và mã lỗi như ANGI_API_Design_Ver1.7; code theo coding_rule.md; unit test tối thiểu 2 method; hiện trên Scalar; PR được Dũng review. | E48: Trọng | F48: ANGI Sprint 1 | G48: EP-DISC | H48: 2 | I48: 15/10/2026 | J48: 16/10/2026 | K48: backend iteration1 | L48: ANGI-60 | N48: 3.7 | O48: Medium
A49: T094 | B49: Task | C49: [FE] F-47 Submit Verification | D49: Use case F-47 Submit Verification (Actor: Restaurant Owner). Allows a Restaurant Owner to submit the information and documents required to request restaurant verification. The system checks that the submission is complete and moves the request to the pending review status. Endpoint cần gọi: - OWN-06 POST /api/v1/owner/restaurant/verifications - MEDIA-01 POST /api/v1/media Tài liệu: ANGI_Use_Case_Basic_Descriptions_Ver1.0 (use case), ANGI_API_Design_Ver1.7 (sheet JSON mẫu để làm mock data, sheet Mã lỗi để hiện thông báo lỗi). DoD: Màn hình chạy với mock data đúng sheet JSON mẫu, chuyển sang API thật khi BE merge; responsive; PR được Dũng review. | E49: Tuấn | F49: ANGI Sprint 1 | G49: EP-REST | H49: 3 | I49: 15/10/2026 | J49: 16/10/2026 | K49: frontend iteration1 | L49: ANGI-61 | N49: 5.5 | O49: Medium
A50: T007 | B50: Task | C50: [BE] F-04 Login with Google | D50: Use case F-04 Login with Google (Actor: Guest). Allows a user to log in or register an ANGI account using a Google account. The system verifies the information from Google, finds or creates the corresponding ANGI account, and establishes a login session for the user. Endpoint cần làm: - AUTH-05 POST /api/v1/auth/google Ghi chú: Xác thực idToken Google, liên kết qua user_external_logins. Tài liệu: ANGI_Use_Case_Basic_Descriptions_Ver1.0 (use case), ANGI_API_Design_Ver1.7 (sheet Backend API, Chi tiết Request-Response, Mã lỗi), ANGI_Data_Dictionary_Ver1.1 (bảng), coding_rule.md. DoD: Endpoint trả đúng request/response và mã lỗi như ANGI_API_Design_Ver1.7; code theo coding_rule.md; unit test tối thiểu 2 method; hiện trên Scalar; PR được Dũng review. | E50: Hưng | F50: ANGI Sprint 1 | G50: EP-AUTH | H50: 3 | I50: 16/10/2026 | J50: 16/10/2026 | K50: backend iteration1 | L50: ANGI-62 | N50: 3.2 | O50: Medium
A51: T026 | B51: Task | C51: [FE] F-13 View Dish Detail | D51: Use case F-13 View Dish Detail (Actor: Guest, Traveler). Allows a Guest or Traveler to view the details of a dish, including its name, description, characteristics, related information, and the restaurant that serves it. Endpoint cần gọi: - DISH-02 GET /api/v1/dishes/{dishId} Tài liệu: ANGI_Use_Case_Basic_Descriptions_Ver1.0 (use case), ANGI_API_Design_Ver1.7 (sheet JSON mẫu để làm mock data, sheet Mã lỗi để hiện thông báo lỗi). DoD: Màn hình chạy với mock data đúng sheet JSON mẫu, chuyển sang API thật khi BE merge; responsive; PR được Tuấn review. | E51: Đức | F51: ANGI Sprint 1 | G51: EP-DISC | H51: 2 | I51: 16/10/2026 | J51: 16/10/2026 | K51: frontend iteration1 | L51: ANGI-63 | N51: 5.2 | O51: Medium
A52: T027 | B52: Task | C52: [BE] F-14 View Corresponding Restaurant Detail | D52: Use case F-14 View Corresponding Restaurant Detail (Actor: Guest, Traveler). Allows a Guest or Traveler to view the details of the eatery/restaurant that serves a specific dish, including basic information, address, location, opening hours, menu, rating, and other related information. Endpoint cần làm: - REST-02 GET /api/v1/restaurants/{restaurantId} - DISH-02 GET /api/v1/dishes/{dishId} Tài liệu: ANGI_Use_Case_Basic_Descriptions_Ver1.0 (use case), ANGI_API_Design_Ver1.7 (sheet Backend API, Chi tiết Request-Response, Mã lỗi), ANGI_Data_Dictionary_Ver1.1 (bảng), coding_rule.md. DoD: Endpoint trả đúng request/response và mã lỗi như ANGI_API_Design_Ver1.7; code theo coding_rule.md; unit test tối thiểu 2 method; hiện trên Scalar; PR được Dũng review. | E52: Trọng | F52: ANGI Sprint 1 | G52: EP-DISC | H52: 1 | I52: 16/10/2026 | J52: 16/10/2026 | K52: backend iteration1 | L52: ANGI-64 | N52: 3.4 | O52: Medium
A53: T096 | B53: Task | C53: [FE] F-48 View Verification Status | D53: Use case F-48 View Verification Status (Actor: Restaurant Owner). Allows a Restaurant Owner to view the current status of the restaurant verification request, such as pending, approved, or rejected, along with any feedback. Endpoint cần gọi: - OWN-07 GET /api/v1/owner/restaurant/verifications Tài liệu: ANGI_Use_Case_Basic_Descriptions_Ver1.0 (use case), ANGI_API_Design_Ver1.7 (sheet JSON mẫu để làm mock data, sheet Mã lỗi để hiện thông báo lỗi). DoD: Màn hình chạy với mock data đúng sheet JSON mẫu, chuyển sang API thật khi BE merge; responsive; PR được Dũng review. | E53: Tuấn | F53: ANGI Sprint 1 | G53: EP-REST | H53: 1 | I53: 16/10/2026 | J53: 16/10/2026 | K53: frontend iteration1 | L53: ANGI-65 | N53: 5.1 | O53: Medium
A54: T009 | B54: Task | C54: [BE] F-05 Forgot Password | D54: Use case F-05 Forgot Password (Actor: Guest). Allows a user to request password recovery when they cannot remember their current password. The user provides the required identifying information; the system checks the account and then sends the information or link needed to reset the password. Endpoint cần làm: - AUTH-08 POST /api/v1/auth/forgot-password Ghi chú: Luôn trả 200 (data null) dù email có tồn tại hay không (AUTH-08); giới hạn 1 lần / 60 giây. Tài liệu: ANGI_Use_Case_Basic_Descriptions_Ver1.0 (use case), ANGI_API_Design_Ver1.7 (sheet Backend API, Chi tiết Request-Response, Mã lỗi), ANGI_Data_Dictionary_Ver1.1 (bảng), coding_rule.md. DoD: Endpoint trả đúng request/response và mã lỗi như ANGI_API_Design_Ver1.7; code theo coding_rule.md; unit test tối thiểu 2 method; hiện trên Scalar; PR được Dũng review. | E54: Hưng | F54: ANGI Sprint 1 | G54: EP-AUTH | H54: 2 | I54: 16/10/2026 | J54: 17/10/2026 | K54: backend iteration1 | L54: ANGI-66 | N54: 2.8 | O54: Medium
A55: T028 | B55: Task | C55: [FE] F-14 View Corresponding Restaurant Detail | D55: Use case F-14 View Corresponding Restaurant Detail (Actor: Guest, Traveler). Allows a Guest or Traveler to view the details of the eatery/restaurant that serves a specific dish, including basic information, address, location, opening hours, menu, rating, and other related information. Endpoint cần gọi: - REST-02 GET /api/v1/restaurants/{restaurantId} - DISH-02 GET /api/v1/dishes/{dishId} Tài liệu: ANGI_Use_Case_Basic_Descriptions_Ver1.0 (use case), ANGI_API_Design_Ver1.7 (sheet JSON mẫu để làm mock data, sheet Mã lỗi để hiện thông báo lỗi). DoD: Màn hình chạy với mock data đúng sheet JSON mẫu, chuyển sang API thật khi BE merge; responsive; PR được Tuấn review. | E55: Đức | F55: ANGI Sprint 1 | G55: EP-DISC | H55: 1 | I55: 16/10/2026 | J55: 17/10/2026 | K55: frontend iteration1 | L55: ANGI-67 | N55: 4.9 | O55: Medium
A56: T098 | B56: Task | C56: [FE] F-49 Resubmit Verification | D56: Use case F-49 Resubmit Verification (Actor: Restaurant Owner). Allows a Restaurant Owner to resubmit a verification request after the previous submission was rejected or more information was requested. The system receives the updated data and creates a new submission for review. Endpoint cần gọi: - OWN-08 POST /api/v1/owner/restaurant/verifications/{verificationId}/resubmit Tài liệu: ANGI_Use_Case_Basic_Descriptions_Ver1.0 (use case), ANGI_API_Design_Ver1.7 (sheet JSON mẫu để làm mock data, sheet Mã lỗi để hiện thông báo lỗi). DoD: Màn hình chạy với mock data đúng sheet JSON mẫu, chuyển sang API thật khi BE merge; responsive; PR được Dũng review. | E56: Tuấn | F56: ANGI Sprint 1 | G56: EP-REST | H56: 2 | I56: 16/10/2026 | J56: 17/10/2026 | K56: frontend iteration1 | L56: ANGI-68 | N56: 4.4 | O56: Medium
A57: T023 | B57: Task | C57: [BE] F-12 Browse Dish | D57: [CRITICAL PATH] Task này nằm trên đường găng: dự phòng tối đa 1 ngày. Phải xong đúng Due Date 17/10/2026; trễ 1 ngày thì mốc "Software Package Version 1" (25/10/2026) bị trễ theo. Ảnh hưởng trực tiếp tới: [BE] F-18 Roll Dish; Code freeze + tích hợp Iteration 1: merge PR vào dev, chạy toàn hệ thống. Cần xong trước khi bắt đầu: Reco client trong backend .NET (IRecommendationService); Reco P1: Cold start (Pooled Wilson) + Content-based, RECO-05 /recommendations, RECO-06 /impressions; Database: ANGIContext schema core, base class, initial migration; Backend: ExceptionHandlingMiddleware, cấu hình JWT, CORS, rate limit; Seed data: nhà hàng đã verify, món, user test cho mọi role. Gặp vướng thì báo ngay trong ngày cho Dũng (PM), không đợi họp. Use case F-12 Browse Dish (Actor: Guest, Traveler). Allows a Guest or Traveler to browse the list of dishes on ANGI. Users can view basic information and use the supported filtering or search options to discover suitable dishes. Endpoint cần làm: - DISH-01 GET /api/v1/dishes - IMP-01 POST /api/v1/impressions - CAT-02 GET /api/v1/tags Ghi chú: Backend lọc ứng viên (tag, giá, bữa…) rồi gọi RECO-05; trả cursor + requestId. App gửi IMP-01 để ghi impression. Tài liệu: ANGI_Use_Case_Basic_Descriptions_Ver1.0 (use case), ANGI_API_Design_Ver1.7 (sheet Backend API, Chi tiết Request-Response, Mã lỗi), ANGI_Data_Dictionary_Ver1.1 (bảng), coding_rule.md. DoD: Endpoint trả đúng request/response và mã lỗi như ANGI_API_Design_Ver1.7; code theo coding_rule.md; unit test tối thiểu 2 method; hiện trên Scalar; PR được Dũng review. | Làm sau: Reco client trong backend .NET (IRecommendationService), Reco P1: Cold start (Pooled Wilson) + Content-based, RECO-05 /recommendations, RECO-06 /impressions. | E57: Trọng | F57: ANGI Sprint 1 | G57: EP-DISC | H57: 3 | I57: 17/10/2026 | J57: 17/10/2026 | K57: backend iteration1 critical-path | L57: ANGI-69 | M57: Có | N57: 1.4 | O57: Highest
A58: T011 | B58: Task | C58: [BE] F-06 Reset Password | D58: Use case F-06 Reset Password (Actor: Guest). Allows a user to set a new password through the password recovery process. The system verifies that the reset request is valid, checks the requirements for the new password, and updates the account's credentials. Endpoint cần làm: - AUTH-09 POST /api/v1/auth/reset-password Ghi chú: Đổi mật khẩu xong thì thu hồi mọi phiên (user_sessions.revoked_at). Tài liệu: ANGI_Use_Case_Basic_Descriptions_Ver1.0 (use case), ANGI_API_Design_Ver1.7 (sheet Backend API, Chi tiết Request-Response, Mã lỗi), ANGI_Data_Dictionary_Ver1.1 (bảng), coding_rule.md. DoD: Endpoint trả đúng request/response và mã lỗi như ANGI_API_Design_Ver1.7; code theo coding_rule.md; unit test tối thiểu 2 method; hiện trên Scalar; PR được Dũng review. | E58: Hưng | F58: ANGI Sprint 1 | G58: EP-AUTH | H58: 2 | I58: 17/10/2026 | J58: 17/10/2026 | K58: backend iteration1 | L58: ANGI-70 | N58: 2.3 | O58: Medium
A59: T033 | B59: Task | C59: [BE] F-17 Set Up Preference Profile | D59: Use case F-17 Set Up Preference Profile (Actor: Traveler). Allows a Traveler to set up an initial preference profile by answering the system's questions on first use, to support the recommendation system. The system stores the answers as the initial input data for the preference profile. Endpoint cần làm: - PREF-02 POST /api/v1/me/preference-survey - PREF-03 POST /api/v1/me/preference-survey/skip Ghi chú: Câu trả lời khảo sát chỉ lưu ở reco: gọi RECO-03 trực tiếp; bỏ qua = PREF-03 gửi answers rỗng. Tài liệu: ANGI_Use_Case_Basic_Descriptions_Ver1.0 (use case), ANGI_API_Design_Ver1.7 (sheet Backend API, Chi tiết Request-Response, Mã lỗi), ANGI_Data_Dictionary_Ver1.1 (bảng), coding_rule.md. DoD: Endpoint trả đúng request/response và mã lỗi như ANGI_API_Design_Ver1.7; code theo coding_rule.md; unit test tối thiểu 2 method; hiện trên Scalar; PR được Hưng review. | Làm sau: Reco P1: User vector từ khảo sát (RECO-03, RECO-09). | E59: Dũng | F59: ANGI Sprint 1 | G59: EP-DISC | H59: 3 | I59: 17/10/2026 | J59: 17/10/2026 | K59: backend iteration1 | L59: ANGI-71 | N59: 2 | O59: Medium
A60: T021 | B60: Task | C60: [BE] F-11 View Home Page | D60: [CRITICAL PATH] Task này nằm trên đường găng: dự phòng tối đa 1 ngày. Phải xong đúng Due Date 18/10/2026; trễ 1 ngày thì mốc "Software Package Version 1" (25/10/2026) bị trễ theo. Ảnh hưởng trực tiếp tới: Code freeze + tích hợp Iteration 1: merge PR vào dev, chạy toàn hệ thống. Cần xong trước khi bắt đầu: Reco P1: Cold start (Pooled Wilson) + Content-based, RECO-05 /recommendations, RECO-06 /impressions; Database: ANGIContext schema core, base class, initial migration; Backend: ExceptionHandlingMiddleware, cấu hình JWT, CORS, rate limit; Seed data: nhà hàng đã verify, món, user test cho mọi role. Gặp vướng thì báo ngay trong ngày cho Dũng (PM), không đợi họp. Use case F-11 View Home Page (Actor: Guest, Traveler). Allows a Guest or Traveler to view the Home Page, which shows information such as trending dishes, top restaurants, highly interacted user blogs, web banners, etc. Endpoint cần làm: - HOME-01 GET /api/v1/home - IMP-01 POST /api/v1/impressions Ghi chú: Món gợi ý lấy qua IRecommendationService (RECO-05). Reco lỗi hoặc quá 800 ms thì xếp theo rating quán (project_architecture.md mục 2). Tài liệu: ANGI_Use_Case_Basic_Descriptions_Ver1.0 (use case), ANGI_API_Design_Ver1.7 (sheet Backend API, Chi tiết Request-Response, Mã lỗi), ANGI_Data_Dictionary_Ver1.1 (bảng), coding_rule.md. DoD: Endpoint trả đúng request/response và mã lỗi như ANGI_API_Design_Ver1.7; code theo coding_rule.md; unit test tối thiểu 2 method; hiện trên Scalar; PR được Dũng review. | Làm sau: Reco P1: Cold start (Pooled Wilson) + Content-based, RECO-05 /recommendations, RECO-06 /impressions. | E60: Trọng | F60: ANGI Sprint 1 | G60: EP-DISC | H60: 3 | I60: 17/10/2026 | J60: 18/10/2026 | K60: backend iteration1 critical-path | L60: ANGI-72 | M60: Có | N60: 1.4 | O60: Highest
A61: T024 | B61: Task | C61: [FE] F-12 Browse Dish | D61: Use case F-12 Browse Dish (Actor: Guest, Traveler). Allows a Guest or Traveler to browse the list of dishes on ANGI. Users can view basic information and use the supported filtering or search options to discover suitable dishes. Endpoint cần gọi: - DISH-01 GET /api/v1/dishes - IMP-01 POST /api/v1/impressions - CAT-02 GET /api/v1/tags Tài liệu: ANGI_Use_Case_Basic_Descriptions_Ver1.0 (use case), ANGI_API_Design_Ver1.7 (sheet JSON mẫu để làm mock data, sheet Mã lỗi để hiện thông báo lỗi). DoD: Màn hình chạy với mock data đúng sheet JSON mẫu, chuyển sang API thật khi BE merge; responsive; PR được Tuấn review. | E61: Đức | F61: ANGI Sprint 1 | G61: EP-DISC | H61: 3 | I61: 17/10/2026 | J61: 18/10/2026 | K61: frontend iteration1 | L61: ANGI-73 | N61: 3.9 | O61: Medium
A62: T034 | B62: Task | C62: [FE] F-17 Set Up Preference Profile | D62: Use case F-17 Set Up Preference Profile (Actor: Traveler). Allows a Traveler to set up an initial preference profile by answering the system's questions on first use, to support the recommendation system. The system stores the answers as the initial input data for the preference profile. Endpoint cần gọi: - PREF-02 POST /api/v1/me/preference-survey - PREF-03 POST /api/v1/me/preference-survey/skip Tài liệu: ANGI_Use_Case_Basic_Descriptions_Ver1.0 (use case), ANGI_API_Design_Ver1.7 (sheet JSON mẫu để làm mock data, sheet Mã lỗi để hiện thông báo lỗi). DoD: Màn hình chạy với mock data đúng sheet JSON mẫu, chuyển sang API thật khi BE merge; responsive; PR được Dũng review. | E62: Tuấn | F62: ANGI Sprint 1 | G62: EP-DISC | H62: 2 | I62: 17/10/2026 | J62: 18/10/2026 | K62: frontend iteration1 | L62: ANGI-74 | N62: 3.6 | O62: Medium
A63: T093 | B63: Task | C63: [BE] F-47 Submit Verification | D63: Use case F-47 Submit Verification (Actor: Restaurant Owner). Allows a Restaurant Owner to submit the information and documents required to request restaurant verification. The system checks that the submission is complete and moves the request to the pending review status. Endpoint cần làm: - OWN-06 POST /api/v1/owner/restaurant/verifications - MEDIA-01 POST /api/v1/media Tài liệu: ANGI_Use_Case_Basic_Descriptions_Ver1.0 (use case), ANGI_API_Design_Ver1.7 (sheet Backend API, Chi tiết Request-Response, Mã lỗi), ANGI_Data_Dictionary_Ver1.1 (bảng), coding_rule.md. DoD: Endpoint trả đúng request/response và mã lỗi như ANGI_API_Design_Ver1.7; code theo coding_rule.md; unit test tối thiểu 2 method; hiện trên Scalar; PR được Dũng review. | E63: Hưng | F63: ANGI Sprint 1 | G63: EP-REST | H63: 3 | I63: 17/10/2026 | J63: 18/10/2026 | K63: backend iteration1 | L63: ANGI-75 | N63: 1.7 | O63: Medium
...

Sheet Gantt
A1: Jira key | B1: Task | C1: Assignee | D1: Start | E1: Due | F1: Float | G1: 05/10 | H1: 06/10 | I1: 07/10 | J1: 08/10 | K1: 09/10 | L1: 10/10 | M1: 11/10 | N1: 12/10 | O1: 13/10 | P1: 14/10 | Q1: 15/10 | R1: 16/10 | S1: 17/10 | T1: 18/10 | U1: 19/10 | V1: 20/10 | W1: 21/10 | X1: 22/10 | Y1: 23/10 | Z1: 24/10 | AA1: 25/10 | AB1: 26/10 | AC1: 27/10 | AD1: 28/10 | AE1: 29/10 | AF1: 30/10 | AG1: 31/10 | AH1: 01/11 | AI1: 02/11 | AJ1: 03/11 | AK1: 04/11 | AL1: 05/11 | AM1: 06/11 | AN1: 07/11 | AO1: 08/11 | AP1: 09/11 | AQ1: 10/11 | AR1: 11/11 | AS1: 12/11 | AT1: 13/11 | AU1: 14/11 | AV1: 15/11 | AW1: 16/11 | AX1: 17/11 | AY1: 18/11 | AZ1: 19/11 | BA1: 20/11 | BB1: 21/11 | BC1: 22/11 | BD1: 23/11 | BE1: 24/11 | BF1: 25/11 | BG1: 26/11 | BH1: 27/11 | BI1: 28/11 | BJ1: 29/11 | BK1: 30/11 | BL1: 01/12 | BM1: 02/12 | BN1: 03/12 | BO1: 04/12 | BP1: 05/12 | BQ1: 06/12 | BR1: 07/12 | BS1: 08/12 | BT1: 09/12 | BU1: 10/12 | BV1: 11/12 | BW1: 12/12 | BX1: 13/12
A2: ANGI-14 | B2: Tạo GitHub repo (backend, frontend, reco), branch strategy, PR template, rule review | C2: Dũng | D2: 05/10/2026 | E2: 05/10/2026 | F2: 8.3
A3: ANGI-15 | B3: Report 4: SDS v1.0 (High Level Design) | C3: Dũng | D3: 05/10/2026 | E3: 05/10/2026 | F3: 69
A4: ANGI-16 | B4: Docker Compose môi trường dev: PostgreSQL 16 + pgvector | C4: Dũng | D4: 05/10/2026 | E4: 06/10/2026 | F4: 8.5
A5: ANGI-17 | B5: Shared service: upload ảnh/tài liệu (Cloudinary) | C5: Hưng | D5: 05/10/2026 | E5: 07/10/2026 | F5: 11.5
A6: ANGI-18 | B6: Shared service: gửi email (Brevo) + template xác minh / reset mật khẩu | C6: Trọng | D6: 05/10/2026 | E6: 08/10/2026 | F6: 10.8
A7: ANGI-19 | B7: Khung Next.js: layout, routing theo role, API client, auth guard, UI kit | C7: Tuấn | D7: 05/10/2026 | E7: 11/10/2026 | F7: 8.1
A8: ANGI-20 | B8: Wireframe/mockup các màn hình Iteration 1 | C8: Đức | D8: 05/10/2026 | E8: 11/10/2026 | F8: 8.1
A9: ANGI-21 | B9: Database: ANGIContext schema core, base class, initial migration | C9: Dũng | D9: 06/10/2026 | E9: 08/10/2026 | F9: 8.5
A10: ANGI-22 | B10: Report 5: Test Planning | C10: Đức | D10: 07/10/2026 | E10: 08/10/2026 | F10: 66
A11: ANGI-23 | B11: Backend: ExceptionHandlingMiddleware, cấu hình JWT, CORS, rate limit | C11: Hưng | D11: 07/10/2026 | E11: 11/10/2026 | F11: 6.4
A12: ANGI-24 | B12: CI GitHub Actions: build + unit test cho .NET, FastAPI, Next.js | C12: Dũng | D12: 08/10/2026 | E12: 09/10/2026 | F12: 65.8
A13: ANGI-25 | B13: Ghi audit log cho thao tác quan trọng | C13: Trọng | D13: 08/10/2026 | E13: 11/10/2026 | F13: 63
... A211: ANGI-223 | B211: Presentation File (slide bảo vệ) | C211: Dũng | D211: 12/12/2026 | E211: 13/12/2026 | F211: 0

Sheet Workload
A1: Thành viên | B1: ANGI Sprint 0 | C1: ANGI Sprint 1 | D1: ANGI Sprint 2 | E1: ANGI Sprint 3 | F1: ANGI Sprint 4 | G1: ANGI Sprint 5 | H1: Tổng
A2: Dũng | B2: =SUMIFS(Backlog!$H:$H,Backlog!$E:$E,$A2,Backlog!$F:$F,"ANGI Sprint 0") -> 26 | C2: =SUMIFS(Backlog!$H:$H,Backlog!$E:$E,$A2,Backlog!$F:$F,"ANGI Sprint 1") -> 31 | D2: =SUMIFS(Backlog!$H:$H,Backlog!$E:$E,$A2,Backlog!$F:$F,"ANGI Sprint 2") -> 27 | E2: =SUMIFS(Backlog!$H:$H,Backlog!$E:$E,$A2,Backlog!$F:$F,"ANGI Sprint 3") -> 17 | F2: =SUMIFS(Backlog!$H:$H,Backlog!$E:$E,$A2,Backlog!$F:$F,"ANGI Sprint 4") -> 4 | G2: =SUMIFS(Backlog!$H:$H,Backlog!$E:$E,$A2,Backlog!$F:$F,"ANGI Sprint 5") -> 7 | H2: =SUM(B2:G2) -> 112
A3: Hưng | B3: =SUMIFS(Backlog!$H:$H,Backlog!$E:$E,$A3,Backlog!$F:$F,"ANGI Sprint 0") -> 5 | C3: =SUMIFS(Backlog!$H:$H,Backlog!$E:$E,$A3,Backlog!$F:$F,"ANGI Sprint 1") -> 33 | D3: =SUMIFS(Backlog!$H:$H,Backlog!$E:$E,$A3,Backlog!$F:$F,"ANGI Sprint 2") -> 27 | E3: =SUMIFS(Backlog!$H:$H,Backlog!$E:$E,$A3,Backlog!$F:$F,"ANGI Sprint 3") -> 22 | F3: =SUMIFS(Backlog!$H:$H,Backlog!$E:$E,$A3,Backlog!$F:$F,"ANGI Sprint 4") -> 3 | G3: =SUMIFS(Backlog!$H:$H,Backlog!$E:$E,$A3,Backlog!$F:$F,"ANGI Sprint 5") -> 0 | H3: =SUM(B3:G3) -> 90
A4: Trọng | B4: =SUMIFS(Backlog!$H:$H,Backlog!$E:$E,$A4,Backlog!$F:$F,"ANGI Sprint 0") -> 4 | C4: =SUMIFS(Backlog!$H:$H,Backlog!$E:$E,$A4,Backlog!$F:$F,"ANGI Sprint 1") -> 30 | D4: =SUMIFS(Backlog!$H:$H,Backlog!$E:$E,$A4,Backlog!$F:$F,"ANGI Sprint 2") -> 33 | E4: =SUMIFS(Backlog!$H:$H,Backlog!$E:$E,$A4,Backlog!$F:$F,"ANGI Sprint 3") -> 26 | F4: =SUMIFS(Backlog!$H:$H,Backlog!$E:$E,$A4,Backlog!$F:$F,"ANGI Sprint 4") -> 3 | G4: =SUMIFS(Backlog!$H:$H,Backlog!$E:$E,$A4,Backlog!$F:$F,"ANGI Sprint 5") -> 0 | H4: =SUM(B4:G4) -> 96
A5: Tuấn | B5: =SUMIFS(Backlog!$H:$H,Backlog!$E:$E,$A5,Backlog!$F:$F,"ANGI Sprint 0") -> 5 | C5: =SUMIFS(Backlog!$H:$H,Backlog!$E:$E,$A5,Backlog!$F:$F,"ANGI Sprint 1") -> 25 | D5: =SUMIFS(Backlog!$H:$H,Backlog!$E:$E,$A5,Backlog!$F:$F,"ANGI Sprint 2") -> 32 | E5: =SUMIFS(Backlog!$H:$H,Backlog!$E:$E,$A5,Backlog!$F:$F,"ANGI Sprint 3") -> 24 | F5: =SUMIFS(Backlog!$H:$H,Backlog!$E:$E,$A5,Backlog!$F:$F,"ANGI Sprint 4") -> 7 | G5: =SUMIFS(Backlog!$H:$H,Backlog!$E:$E,$A5,Backlog!$F:$F,"ANGI Sprint 5") -> 0 | H5: =SUM(B5:G5) -> 93
A6: Đức | B6: =SUMIFS(Backlog!$H:$H,Backlog!$E:$E,$A6,Backlog!$F:$F,"ANGI Sprint 0") -> 5 | C6: =SUMIFS(Backlog!$H:$H,Backlog!$E:$E,$A6,Backlog!$F:$F,"ANGI Sprint 1") -> 34 | D6: =SUMIFS(Backlog!$H:$H,Backlog!$E:$E,$A6,Backlog!$F:$F,"ANGI Sprint 2") -> 31 | E6: =SUMIFS(Backlog!$H:$H,Backlog!$E:$E,$A6,Backlog!$F:$F,"ANGI Sprint 3") -> 19 | F6: =SUMIFS(Backlog!$H:$H,Backlog!$E:$E,$A6,Backlog!$F:$F,"ANGI Sprint 4") -> 8 | G6: =SUMIFS(Backlog!$H:$H,Backlog!$E:$E,$A6,Backlog!$F:$F,"ANGI Sprint 5") -> 0 | H6: =SUM(B6:G6) -> 97
A8: Đơn vị: story point. Dũng gánh thêm việc PM nên tải code để thấp hơn các bạn khác.
